Workbook

Sheet README
A1: NP-MT-RNM interaction corpus
A2: Supplementary Data 1 to: Workineh Z.G., Chemorion F.K. & Noailly J. A systems-level network model reveals mechanical regulation of nucleus pulposus cell states.
A4: What this file contains
A5: Content | B5: The literature-curated regulatory interactions of the nucleus pulposus (NP) mechanotransduction regulatory network model (RNM): one row per directed, signed interaction, with the supporting experimental context and references.
A6: Interactions | B6: =COUNTA(Interactions!A:A)-1 -> 353
A7: Nodes with at least one interaction | B7: 146
A8: Model and code | B8: Model, simulation code and SBML: np-mt-rnm, https://doi.org/10.5281/zenodo.23195857. Interactive web application: np-mt-rnm-web, https://doi.org/10.5281/zenodo.23204747.
A10: Sheets
A11: Interactions | B11: One row per interaction (source → target), its regulation and sign, functional modules, experimental context as reported, references with DOI/PMID, evidence notes and retraction screen.
A12: Summary statistics | B12: Counts by cell type, species, experimental setting and functional module, with charts. All values are formulas on 'Interactions'.
A13: Evidence review | B13: 37 interactions whose supporting evidence was added or re-examined during curation, with the evidence class and its limitations.
A14: Retraction screen | B14: Crossref check of every cited DOI for retraction, withdrawal or expression-of-concern notices.
A16: Columns of 'Interactions'
A17: Interaction ID | B17: Stable identifier NPMT-I001 … NPMT-I353.
A18: Source / Target | B18: Regulator and regulated node, using the node names of the model (Supplementary Table S1). Suffixes -M and -E denote Normal- and Hyper-loading state variables of the same molecule.
A19: Regulation / Sign | B19: activation (+1) or inhibition (−1). Sign is derived from Regulation.
A20: Source / Target module | B20: Primary functional module of each node, as used in the manuscript's figures.
A21: Cell type, Experimental model, Culture (as reported) | B21: Experimental context of the supporting evidence, as recorded during curation. 'Not reported' where it was not recorded.
A22: Cell-type group / Species group / Culture group | B22: Harmonised groups used for the summary statistics (definitions below).
A23: Reference(s) | B23: Full citation(s) of the supporting publication(s). DOI(s) and PMID(s) are extracted into their own columns; the first DOI is a link.
A24: Evidence note | B24: Evidence class and limitation for the 37 reviewed interactions (highlighted).
A25: Retraction screen | B25: Result of the Crossref check for the DOI(s) in that row.
A26: Also cited in falsification benchmark | B26: Marks the interactions whose reference is also cited in the falsification benchmark (Supplementary Table S2).
A28: Definitions
A29: Unit of observation | B29: An interaction (row). One publication can support several interactions, so percentages describe interactions, not publications.
A30: Cell-type group | B30: Any NP / nucleus pulposus label (including NP/chondrocyte) → NP. Otherwise chondrocyte or cartilage → Chondrocyte / cartilage. All other, general or missing labels → Other / not reported.
A31: Species group | B31: Human, human + animal and recognised human cell lines → Human. Otherwise rat, mouse or murine → Animal. All other species and unspecified → Other / unspecified.
A32: Culture group | B32: In vitro, Ex vivo or In vivo when only one setting is recorded; Mixed when several are; Not reported when the field is empty.
A34: Limitations
A35: Evidence strength | B35: Most interactions are supported by direct experimental evidence in NP cells, chondrocytes or related cells. A minority rely on indirect, pathway-level, contextual or conflicting evidence; these are listed in 'Evidence review'. The presence of a reference is not by itself proof of the modelled sign.
A36: Experimental context | B36: Cell type, model and culture were not recorded for every interaction (see the 'Not reported' counts in 'Summary statistics').
A37: References without DOI | B37: Could not be included in the automated retraction screen.
A39: How to cite
A40: Paper | B40: Workineh Z.G., Chemorion F.K. & Noailly J. A systems-level network model reveals mechanical regulation of nucleus pulposus cell states. (2026).
A41: Software and data | B41: Workineh Z.G., Chemorion F.K. & Noailly J. np-mt-rnm. Zenodo (2026). https://doi.org/10.5281/zenodo.23195857
A42: Version | B42: Corpus of 353 interactions; file generated 2026-10-11.

Sheet Interactions
A1: Interaction ID | B1: Source | C1: Regulation | D1: Target | E1: Sign | F1: Source module | G1: Target module | H1: Cell type (as reported) | I1: Cell-type group | J1: Experimental model (as reported) | K1: Species group | L1: Culture (as reported) | M1: Culture group | N1: Reference(s) | O1: DOI(s) | P1: PMID(s) | Q1: Evidence note | R1: Retraction screen | S1: Also cited in falsification benchmark (Table S2)
A2: NPMT-I001 | B2: HIF-1α | C2: activation | D2: ACAN | E2: =IF(C2="inhibition",-1,1) -> 1 | F2: Transcription Factors | G2: ECM anabolism & phenotype markers | H2: Nucleus pulposus | I2: NP / nucleus pulposus | J2: Human NP cells | K2: Human | L2: In vitro | M2: In vitro | N2: Liu Z, Li C, Meng X, Bai Y, Qi J, Wang J, Zhou Q, Zhang W, Zhang X. Hypoxia-inducible factor-1α mediates aggrecan and collagen II expression via NOTCH1 signaling in nucleus pulposus cells during intervertebral disc degeneration. Biochem Biophys Res Commun. 2017;488(3):554-561. doi: 10.1016/j.bbrc.2017.05.086. PMID: 28526405. | O2: 10.1016/j.bbrc.2017.05.086 | P2: 28526405 | Q2: Supported in NP — HIF-1α overexpression increased aggrecan | R2: No notice found
A3: NPMT-I002 | B3: PPARγ | C3: activation | D3: ACAN | E3: =IF(C3="inhibition",-1,1) -> 1 | F3: Transcription Factors | G3: ECM anabolism & phenotype markers | H3: NP | I3: NP / nucleus pulposus | J3: Human/Rat | K3: Human | L3: 2D, in vitro | M3: In vitro | N3: Cheng P, Wei HZ, Chen HW, Wang ZQ, Mao P, Zhang HH. DNMT3a-mediated methylation of PPARγ promote intervertebral disc degeneration by regulating the NF-κB pathway. J Cell Mol Med. 2024 Jan;28(2):e18048. doi: 10.1111/jcmm.18048. Epub 2023 Nov 20. PMID: 37986543; PMCID: PMC10826446. | O3: 10.1111/jcmm.18048 | P3: 37986543 | R3: No notice found
A4: NPMT-I003 | B4: SOX9 | C4: activation | D4: ACAN | E4: =IF(C4="inhibition",-1,1) -> 1 | F4: Transcription Factors | G4: ECM anabolism & phenotype markers | H4: NP | I4: NP / nucleus pulposus | J4: rat | K4: Animal | L4: 3D, in vitro | M4: In vitro | N4: Cheng CC, Uchiyama Y, Hiyama A, Gajghate S, Shapiro IM, Risbud MV. PI3K/AKT regulates aggrecan gene expression by modulating Sox9 expression and activity in nucleus pulposus cells of the intervertebral disc. J Cell Physiol. 2009 Dec;221(3):668-76. doi: 10.1002/jcp.21904. PMID: 19711351; PMCID: PMC3042319. | O4: 10.1002/jcp.21904 | P4: 19711351 | R4: No notice found
A5: NPMT-I004 | B5: HIF-2α | C5: activation | D5: ADAMTS4/5 | E5: =IF(C5="inhibition",-1,1) -> 1 | F5: Transcription Factors | G5: Cytokines, chemokines, proteases & others | H5: NP | I5: NP / nucleus pulposus | J5: human | K5: Human | L5: 2D, in vitro | M5: In vitro | N5: Huang Y, Wang Y, Wu C, Tian W. Elevated expression of hypoxia-inducible factor-2alpha regulated catabolic factors during intervertebral disc degeneration. Life Sci. 2019 Sep 1;232:116565. doi: 10.1016/j.lfs.2019.116565. Epub 2019 Jun 26. PMID: 31251999. | O5: 10.1016/j.lfs.2019.116565 | P5: 31251999 | R5: No notice found
A6: NPMT-I005 | B6: JNK | C6: activation | D6: ADAMTS4/5 | E6: =IF(C6="inhibition",-1,1) -> 1 | F6: MAPK & stress-activated kinases | G6: Cytokines, chemokines, proteases & others | H6: NP | I6: NP / nucleus pulposus | J6: human | K6: Human | L6: 2d, in vitro | M6: In vitro | N6: Li JK, Nie L, Zhao YP, Zhang YQ, Wang X, Wang SS, Liu Y, Zhao H, Cheng L. IL-17 mediates inflammatory reactions via p38/c-Fos and JNK/c-Jun activation in an AP-1-dependent manner in human nucleus pulposus cells. J Transl Med. 2016 Mar 17;14:77. doi: 10.1186/s12967-016-0833-9. PMID: 26988982; PMCID: PMC4794827. | O6: 10.1186/s12967-016-0833-9 | P6: 26988982 | R6: No notice found
A7: NPMT-I006 | B7: NF-κB | C7: activation | D7: ADAMTS4/5 | E7: =IF(C7="inhibition",-1,1) -> 1 | F7: Transcription Factors | G7: Cytokines, chemokines, proteases & others | H7: NP | I7: NP / nucleus pulposus | J7: Human | K7: Human | L7: 2D, in vitro | M7: In vitro | N7: Sun Z, Yin Z, Liu C, Liang H, Jiang M, Tian J. IL-1β promotes ADAMTS enzyme-mediated aggrecan degradation through NF-κB in human intervertebral disc. J Orthop Surg Res. 2015 Oct 6;10:159. doi: 10.1186/s13018-015-0296-3. PMID: 26438479; PMCID: PMC4594913. | O7: 10.1186/s13018-015-0296-3 | P7: 26438479 | R7: No notice found
A8: NPMT-I007 | B8: P38 | C8: activation | D8: ADAMTS4/5 | E8: =IF(C8="inhibition",-1,1) -> 1 | F8: MAPK & stress-activated kinases | G8: Cytokines, chemokines, proteases & others | H8: Chondrocytes | I8: Chondrocyte / cartilage | J8: Human osteoarthritic chondrocytes | K8: Human | L8: In vitro | M8: In vitro | N8: Xue J, Wang J, Liu Q, Luo A. Tumor necrosis factor-α induces ADAMTS-4 expression in human osteoarthritis chondrocytes. Mol Med Rep. 2013;8(6):1755-1760. doi: 10.3892/mmr.2013.1729. PMID: 24126638. | O8: 10.3892/mmr.2013.1729 | P8: 24126638 | Q8: Partial: ADAMTS4 only — p38 dependent TNF-α induction of ADAMTS4; NOT demonstrated for ADAMTS5 | R8: No notice found
A9: NPMT-I008 | B9: PPARγ | C9: inhibition | D9: ADAMTS4/5 | E9: =IF(C9="inhibition",-1,1) -> -1 | F9: Transcription Factors | G9: Cytokines, chemokines, proteases & others | H9: NP | I9: NP / nucleus pulposus | J9: Human/Rat | K9: Human | L9: 2D, in vitro | M9: In vitro | N9: Cheng P, Wei HZ, Chen HW, Wang ZQ, Mao P, Zhang HH. DNMT3a-mediated methylation of PPARγ promote intervertebral disc degeneration by regulating the NF-κB pathway. J Cell Mol Med. 2024 Jan;28(2):e18048. doi: 10.1111/jcmm.18048. Epub 2023 Nov 20. PMID: 37986543; PMCID: PMC10826446. | O9: 10.1111/jcmm.18048 | P9: 37986543 | R9: No notice found
A10: NPMT-I009 | B10: mTORC2 | C10: activation | D10: AKT1-E | E10: =IF(C10="inhibition",-1,1) -> 1 | F10: Metabolic & related | G10: Metabolic & related | H10: NP | I10: NP / nucleus pulposus | J10: human | K10: Human | L10: 2D, in vitro | M10: In vitro | N10: Ito M, Yurube T, Kakutani K, Maeno K, Takada T, Terashima Y, Kakiuchi Y, Takeoka Y, Miyazaki S, Kuroda R, Nishida K. Selective interference of mTORC1/RAPTOR protects against human disc cellular apoptosis, senescence, and extracellular matrix catabolism with Akt and autophagy induction. Osteoarthritis Cartilage. 2017 Dec;25(12):2134-2146. doi: 10.1016/j.joca.2017.08.019. Epub 2017 Sep 6. PMID: 28888905. | O10: 10.1016/j.joca.2017.08.019 | P10: 28888905 | R10: No notice found
A11: NPMT-I010 | B11: PDK1-E | C11: activation | D11: AKT1-E | E11: =IF(C11="inhibition",-1,1) -> 1 | F11: Metabolic & related | G11: Metabolic & related | H11: Not reported | I11: Other / not reported | J11: Not reported | K11: Other / unspecified | L11: Not reported | M11: Not reported | N11: Dangelmaier C, Manne BK, Liverani E, Jin J, Bray P, Kunapuli SP. PDK1 selectively phosphorylates Thr(308) on Akt and contributes to human platelet functional responses. Thromb Haemost. 2014 Mar 3;111(3):508-17. doi: 10.1160/TH13-06-0484. Epub 2013 Dec 19. PMID: 24352480; PMCID: PMC4079046. | O11: 10.1160/th13-06-0484 | P11: 24352480 | R11: No notice found
A12: NPMT-I011 | B12: PIP3-M | C12: inhibition | D12: AKT1-E | E12: =IF(C12="inhibition",-1,1) -> -1 | F12: Metabolic & related | G12: Metabolic & related | H12: Not reported | I12: Other / not reported | J12: Not reported | K12: Other / unspecified | L12: Not reported | M12: Not reported | N12: Stokoe D, Stephens LR, Copeland T, Gaffney PR, Reese CB, Painter GF, Holmes AB, McCormick F, Hawkins PT. Dual role of phosphatidylinositol-3,4,5-trisphosphate in the activation of protein kinase B. Science. 1997;277(5325):567-570. doi: 10.1126/science.277.5325.567. PMID: 9228007. | O12: 10.1126/science.277.5325.567 | P12: 9228007 | Q12: Contextual; direction conflicts — PIP3 recruits and promotes activation of AKT; no M-to-E cross-compartment inhibition shown. Cited because it directly studies PIP3 and AKT1, but it supports activation and does not validate negative sign or M/E topology | R12: No notice found
A13: NPMT-I012 | B13: mTORC2 | C13: activation | D13: AKT1-M | E13: =IF(C13="inhibition",-1,1) -> 1 | F13: Metabolic & related | G13: Metabolic & related | H13: NP | I13: NP / nucleus pulposus | J13: human | K13: Human | L13: 2D, in vitro | M13: In vitro | N13: Ito M, Yurube T, Kakutani K, Maeno K, Takada T, Terashima Y, Kakiuchi Y, Takeoka Y, Miyazaki S, Kuroda R, Nishida K. Selective interference of mTORC1/RAPTOR protects against human disc cellular apoptosis, senescence, and extracellular matrix catabolism with Akt and autophagy induction. Osteoarthritis Cartilage. 2017 Dec;25(12):2134-2146. doi: 10.1016/j.joca.2017.08.019. Epub 2017 Sep 6. PMID: 28888905. | O13: 10.1016/j.joca.2017.08.019 | P13: 28888905 | R13: No notice found
A14: NPMT-I013 | B14: PDK1-M | C14: activation | D14: AKT1-M | E14: =IF(C14="inhibition",-1,1) -> 1 | F14: Metabolic & related | G14: Metabolic & related | H14: Not reported | I14: Other / not reported | J14: Not reported | K14: Other / unspecified | L14: Not reported | M14: Not reported | N14: Dangelmaier C, Manne BK, Liverani E, Jin J, Bray P, Kunapuli SP. PDK1 selectively phosphorylates Thr(308) on Akt and contributes to human platelet functional responses. Thromb Haemost. 2014 Mar 3;111(3):508-17. doi: 10.1160/TH13-06-0484. Epub 2013 Dec 19. PMID: 24352480; PMCID: PMC4079046. | O14: 10.1160/th13-06-0484 | P14: 24352480 | R14: No notice found
A15: NPMT-I014 | B15: PIP3-E | C15: inhibition | D15: AKT1-M | E15: =IF(C15="inhibition",-1,1) -> -1 | F15: Metabolic & related | G15: Metabolic & related | H15: Not reported | I15: Other / not reported | J15: Not reported | K15: Other / unspecified | L15: Not reported | M15: Not reported | N15: Stokoe D, Stephens LR, Copeland T, Gaffney PR, Reese CB, Painter GF, Holmes AB, McCormick F, Hawkins PT. Dual role of phosphatidylinositol-3,4,5-trisphosphate in the activation of protein kinase B. Science. 1997;277(5325):567-570. doi: 10.1126/science.277.5325.567. PMID: 9228007. | O15: 10.1126/science.277.5325.567 | P15: 9228007 | Q15: Contextual; direction conflicts — PIP3 recruits and promotes activation of AKT; no E-to-M cross-compartment inhibition shown. Same primary paper supports generic PIP3–AKT molecular interaction, not negative sign or compartment-specific effect | R15: No notice found
A16: NPMT-I015 | B16: Ca2+os | C16: activation | D16: AMPK | E16: =IF(C16="inhibition",-1,1) -> 1 | F16: Ion channels & related | G16: Metabolic & related | H16: Not reported | I16: Other / not reported | J16: Not reported | K16: Other / unspecified | L16: Not reported | M16: Not reported | N16: Woods A, Dickerson K, Heath R, et al. Ca2+/calmodulin-dependent protein kinase kinase-beta acts upstream of AMP-activated protein kinase in mammalian cells. Cell Metab. 2005;2(1):21-33. doi: 10.1016/j.cmet.2005.06.005. PMID: 16054096. | O16: 10.1016/j.cmet.2005.06.005 | P16: 16054096 | Q16: Indirect mechanistic support — Ca2+ can activate AMPK via CaMKKβ; osmotic compartment not tested. | R16: No notice found
A17: NPMT-I016 | B17: LKB1 | C17: activation | D17: AMPK | E17: =IF(C17="inhibition",-1,1) -> 1 | F17: Metabolic & related | G17: Metabolic & related | H17: Chondrocyte | I17: Chondrocyte / cartilage | J17: mouse | K17: Animal | L17: 2D, in vitro | M17: In vitro | N17: Petursson F, Husa M, June R, Lotz M, Terkeltaub R, Liu-Bryan R. Linked decreases in liver kinase B1 and AMP-activated protein kinase activity modulate matrix catabolic responses to biomechanical injury in chondrocytes. Arthritis Res Ther. 2013 Jul 25;15(4):R77. doi: 10.1186/ar4254. PMID: 23883619; PMCID: PMC3979085. | O17: 10.1186/ar4254 | P17: 23883619 | R17: No notice found
A18: NPMT-I017 | B18: ROS | C18: activation | D18: AMPK | E18: =IF(C18="inhibition",-1,1) -> 1 | F18: Oxidative-stress defense & proteostasis | G18: Metabolic & related | H18: Other cells | I18: Other / not reported | J18: Mouse embryonic fibroblasts / osteosarcoma cells | K18: Animal | L18: In vitro | M18: In vitro | N18: Emerling BM, Weinberg F, Snyder C, Burgess Z, Mutlu GM, Viollet B, Budinger GRS, Chandel NS. Hypoxic activation of AMPK is dependent on mitochondrial ROS but independent of an increase in AMP/ATP ratio. Free Radic Biol Med. 2009;46(10):1386-1391. doi: 10.1016/j.freeradbiomed.2009.02.019. PMID: 19268526. | O18: 10.1016/j.freeradbiomed.2009.02.019 | P18: 19268526 | Q18: Supported in other cells — ROS-dependent AMPK activation in hypoxic cultured cells; not NP-specific | R18: No notice found
A19: NPMT-I018 | B19: mTORC1 | C19: inhibition | D19: AMPK | E19: =IF(C19="inhibition",-1,1) -> -1 | F19: Metabolic & related | G19: Metabolic & related | H19: Not reported | I19: Other / not reported | J19: Not reported | K19: Other / unspecified | L19: Not reported | M19: Not reported | N19: Ling NXY, Kaczmarek A, Hoque A, Davie E, Ngoei KRW, Morrison KR, Smiles WJ, Forte GM, Wang T, Lie S, Dite TA, Langendorf CG, Scott JW, Oakhill JS, Petersen J. mTORC1 directly inhibition AMPK to promote cell proliferation under nutrient stress. Nat Metab. 2020 Jan;2(1):41-49. doi: 10.1038/s42255-019-0157-1. Epub 2020 Jan 20. PMID: 31993556; PMCID: PMC6986917. | O19: 10.1038/s42255-019-0157-1 | P19: 31993556 | R19: No notice found
A20: NPMT-I019 | B20: CREB | C20: activation | D20: ANXA1 | E20: =IF(C20="inhibition",-1,1) -> 1 | F20: Transcription Factors | G20: Other / unclassified | H20: General | I20: Other / not reported | J20: Not reported | K20: Other / unspecified | L20: Not reported | M20: Not reported | N20: Antonicelli F, De Coupade C, Russo-Marie F, Le Garrec Y. CREB is involved in mouse annexin A1 regulation by cAMP and glucocorticoids. Eur J Biochem. 2001 Jan;268(1) | R20: Not screened (no DOI)
A21: NPMT-I020 | B21: ERK-E | C21: activation | D21: AP-1 | E21: =IF(C21="inhibition",-1,1) -> 1 | F21: MAPK & stress-activated kinases | G21: Transcription Factors | H21: Chondrocyte | I21: Chondrocyte / cartilage | J21: rat | K21: Animal | L21: Not reported | M21: Not reported | N21: Papachristou DJ, Pirttiniemi P, Kantomaa T, Papavassiliou AG, Basdra EK. JNK/ERK-AP-1/Runx2 induction "paves the way" to cartilage load-ignited chondroblastic differentiation. Histochem Cell Biol. 2005 Sep;124(3-4):215-23. doi: 10.1007/s00418-005-0026-8. Epub 2005 Oct 28. PMID: 16041628. | O21: 10.1007/s00418-005-0026-8 | P21: 16041628 | R21: No notice found
A22: NPMT-I021 | B22: JNK | C22: activation | D22: AP-1 | E22: =IF(C22="inhibition",-1,1) -> 1 | F22: MAPK & stress-activated kinases | G22: Transcription Factors | H22: NP | I22: NP / nucleus pulposus | J22: human | K22: Human | L22: 2d, in vitro | M22: In vitro | N22: Li JK, Nie L, Zhao YP, Zhang YQ, Wang X, Wang SS, Liu Y, Zhao H, Cheng L. IL-17 mediates inflammatory reactions via p38/c-Fos and JNK/c-Jun activation in an AP-1-dependent manner in human nucleus pulposus cells. J Transl Med. 2016 Mar 17;14:77. doi: 10.1186/s12967-016-0833-9. PMID: 26988982; PMCID: PMC4794827. | O22: 10.1186/s12967-016-0833-9 | P22: 26988982 | R22: No notice found
A23: NPMT-I022 | B23: P38 | C23: activation | D23: AP-1 | E23: =IF(C23="inhibition",-1,1) -> 1 | F23: MAPK & stress-activated kinases | G23: Transcription Factors | H23: NP | I23: NP / nucleus pulposus | J23: human | K23: Human | L23: 2d, in vitro | M23: In vitro | N23: Li JK, Nie L, Zhao YP, Zhang YQ, Wang X, Wang SS, Liu Y, Zhao H, Cheng L. IL-17 mediates inflammatory reactions via p38/c-Fos and JNK/c-Jun activation in an AP-1-dependent manner in human nucleus pulposus cells. J Transl Med. 2016 Mar 17;14:77. doi: 10.1186/s12967-016-0833-9. PMID: 26988982; PMCID: PMC4794827. | O23: 10.1186/s12967-016-0833-9 | P23: 26988982 | R23: No notice found
A24: NPMT-I023 | B24: PPARγ | C24: inhibition | D24: AP-1 | E24: =IF(C24="inhibition",-1,1) -> -1 | F24: Transcription Factors | G24: Transcription Factors | H24: chondrocyte | I24: Chondrocyte / cartilage | J24: Human | K24: Human | L24: 2D, in vitro | M24: In vitro | N24: Fahmi H, Di Battista JA, Pelletier JP, Mineau F, Ranger P, Martel-Pelletier J. Peroxisome proliferator--activated receptor gamma activators inhibit interleukin-1beta-induced nitric oxide and matrix metalloproteinase 13 production in human chondrocytes. Arthritis Rheum. 2001 Mar;44(3):595-607. doi: 10.1002/1529-0131(200103)44:3<595::AID-ANR108>3.0.CO;2-8. PMID: 11263774. | O24: 10.1002/1529-0131(200103)44:3<595::aid-anr108>3.0.co;2-8 | P24: 11263774 | R24: No notice found
A25: NPMT-I024 | B25: SOX9 | C25: inhibition | D25: AP-1 | E25: =IF(C25="inhibition",-1,1) -> -1 | F25: Transcription Factors | G25: Transcription Factors | H25: Chondrocytes; epidermal stem cells | I25: Chondrocyte / cartilage | J25: Mouse chondrocytes; epidermal stem cells | K25: Animal | L25: In vivo / in vitro | M25: Mixed | N25: He X, Ohba S, Hojo H, McMahon AP. AP-1 family members act with Sox9 to promote chondrocyte hypertrophy. Development. 2016;143(16):3012-3023. doi: 10.1242/dev.134502. PMID: 27471255. Yang Y, Gomez N, Infarinato N, et al. The pioneer factor SOX9 competes for epigenetic factors to switch stem cell fates. Nat Cell Biol. 2023;25:1185-1195. doi: 10.1038/s41556-023-01184-y. [Evidence caveat: Context-dependent cooperation or altered occupancy; not general inhibition.] | O25: 10.1242/dev.134502; 10.1038/s41556-023-01184-y | P25: 27471255 | Q25: contextual / conflicting, NOT sign-validated — Context-dependent cooperation or altered occupancy; not general inhibition. | R25: No notice found
A26: NPMT-I025 | B26: HIF-1α | C26: activation | D26: AQP1 | E26: =IF(C26="inhibition",-1,1) -> 1 | F26: Transcription Factors | G26: Ion channels & related | H26: NP | I26: NP / nucleus pulposus | J26: Human/Rat | K26: Human | L26: 2D, in vitro | M26: In vitro | N26: Johnson ZI, Gogate SS, Day R, Binch A, Markova DZ, Chiverton N, Cole A, Conner M, Shapiro IM, Le Maitre CL, Risbud MV. Aquaporin 1 and 5 expression decreases during human intervertebral disc degeneration: Novel HIF-1-mediated regulation of aquaporins in NP cells. Oncotarget. 2015 May 20;6(14):11945-58. doi: 10.18632/oncotarget.3631. PMID: 25844601; PMCID: PMC4494915. | O26: 10.18632/oncotarget.3631 | P26: 25844601 | R26: No notice found
A27: NPMT-I026 | B27: TonEBP | C27: activation | D27: AQP1 | E27: =IF(C27="inhibition",-1,1) -> 1 | F27: Transcription Factors | G27: Ion channels & related | H27: NP | I27: NP / nucleus pulposus | J27: human | K27: Human | L27: 3D, in vitro | M27: In vitro | N27: Snuggs, J.W., Tessier, S., Bunning, R.A.B. et al. TonEBP regulates the hyperosmotic expression of aquaporin 1 and 5 in the intervertebral disc. Sci Rep 11, 3164 (2021). https://doi.org/10.1038/s41598-021-81838-9 | O27: 10.1038/s41598-021-81838-9 | R27: No notice found
A28: NPMT-I027 | B28: ROS | C28: inhibition | D28: AQP1 | E28: =IF(C28="inhibition",-1,1) -> -1 | F28: Oxidative-stress defense & proteostasis | G28: Ion channels & related | H28: General | I28: Other / not reported | J28: Not reported | K28: Other / unspecified | L28: Not reported | M28: Not reported | N28: Sada K, Nishikawa T, Kukidome D, Yoshinaga T, Kajihara N, Sonoda K, Senokuchi T, Motoshima H, Matsumura T, Araki E. Hyperglycemia Induces Cellular Hypoxia through Production of Mitochondrial ROS Followed by Suppression of Aquaporin-1. PLoS One. 2016 Jul 6;11(7):e0158619. doi: 10.1371/journal.pone.0158619. PMID: 27383386; PMCID: PMC4934928. | O28: 10.1371/journal.pone.0158619 | P28: 27383386 | R28: No notice found
A29: NPMT-I028 | B29: HIF-1α | C29: activation | D29: AQP5 | E29: =IF(C29="inhibition",-1,1) -> 1 | F29: Transcription Factors | G29: Ion channels & related | H29: NP | I29: NP / nucleus pulposus | J29: Human/Rat | K29: Human | L29: 2D, in vitro | M29: In vitro | N29: Johnson ZI, Gogate SS, Day R, Binch A, Markova DZ, Chiverton N, Cole A, Conner M, Shapiro IM, Le Maitre CL, Risbud MV. Aquaporin 1 and 5 expression decreases during human intervertebral disc degeneration: Novel HIF-1-mediated regulation of aquaporins in NP cells. Oncotarget. 2015 May 20;6(14):11945-58. doi: 10.18632/oncotarget.3631. PMID: 25844601; PMCID: PMC4494915. | O29: 10.18632/oncotarget.3631 | P29: 25844601 | R29: No notice found
A30: NPMT-I029 | B30: TonEBP | C30: activation | D30: AQP5 | E30: =IF(C30="inhibition",-1,1) -> 1 | F30: Transcription Factors | G30: Ion channels & related | H30: NP | I30: NP / nucleus pulposus | J30: human | K30: Human | L30: 3D, in vitro | M30: In vitro | N30: Snuggs, J.W., Tessier, S., Bunning, R.A.B. et al. TonEBP regulates the hyperosmotic expression of aquaporin 1 and 5 in the intervertebral disc. Sci Rep 11, 3164 (2021). https://doi.org/10.1038/s41598-021-81838-9 | O30: 10.1038/s41598-021-81838-9 | R30: No notice found
A31: NPMT-I030 | B31: ROS | C31: inhibition | D31: AQP5 | E31: =IF(C31="inhibition",-1,1) -> -1 | F31: Oxidative-stress defense & proteostasis | G31: Ion channels & related | H31: General | I31: Other / not reported | J31: Not reported | K31: Other / unspecified | L31: Not reported | M31: Not reported | N31: Mlinarić M, Lučić I, Tomljanović M, Tartaro Bujak I, Milković L, Čipak Gašparović A. AQP3 and AQP5 Modulation in Response to Prolonged Oxidative Stress in Breast Cancer Cell Lines. Antioxidants (Basel). 2024 May 21;13(6):626. doi: 10.3390/antiox13060626. PMID: 38929065; PMCID: PMC11200458. | O31: 10.3390/antiox13060626 | P31: 38929065 | R31: No notice found
A32: NPMT-I031 | B32: JNK | C32: activation | D32: BAD | E32: =IF(C32="inhibition",-1,1) -> 1 | F32: MAPK & stress-activated kinases | G32: Other / unclassified | H32: NP | I32: NP / nucleus pulposus | J32: human | K32: Human | L32: 2d, in vitro | M32: In vitro | N32: Zou M, Chen W, Li J, Qi X, Wang X, Liu F, Hu J, Zhang Q. Apoptosis Signal-Regulated Kinase-1 Promotes Nucleus Pulposus Cell Senescence and Apoptosis to Regulate Intervertebral Disc Degeneration. Am J Pathol. 2024 Sep;194(9):1737-1751. doi: 10.1016/j.ajpath.2024.05.004. Epub 2024 Jun 13. PMID: 38879082. | O32: 10.1016/j.ajpath.2024.05.004 | P32: 38879082 | R32: No notice found
A33: NPMT-I032 | B33: AKT1-M | C33: inhibition | D33: BAD | E33: =IF(C33="inhibition",-1,1) -> -1 | F33: Metabolic & related | G33: Other / unclassified | H33: Cartilage tissue | I33: Chondrocyte / cartilage | J33: Mouse | K33: Animal | L33: In vivo | M33: In vivo | N33: Qian J, Zhao P, Xu Q, Yang W, Cai R. Swimming prevents cell death of chondrocytes via PI3K/AKT pathway in an experimental model. J Orthop Surg Res. 2023 Jun 17;18(1):439. doi: 10.1186/s13018-023-03815-4. PMID: 37328786; PMCID: PMC10276397. | O33: 10.1186/s13018-023-03815-4 | P33: 37328786 | R33: No notice found
A34: NPMT-I033 | B34: ROS | C34: activation | D34: BAX | E34: =IF(C34="inhibition",-1,1) -> 1 | F34: Oxidative-stress defense & proteostasis | G34: Cell survival, apoptosis & mitophagy/DNA-damage | H34: chondrocyte | I34: Chondrocyte / cartilage | J34: rat | K34: Animal | L34: 2D, in vitro | M34: In vitro | N34: Gao G, Ding H, Zhuang C, Fan W. Effects of Hesperidin on H₂O₂-Treated Chondrocytes and Cartilage in a Rat Osteoarthritis Model. Med Sci Monit. 2018 Dec 17;24:9177-9186. doi: 10.12659/MSM.913726. PMID: 30557884; PMCID: PMC6319163. | O34: 10.12659/msm.913726 | P34: 30557884 | R34: No notice found
A35: NPMT-I034 | B35: Bcl2 | C35: inhibition | D35: BAX | E35: =IF(C35="inhibition",-1,1) -> -1 | F35: Cell survival, apoptosis & mitophagy/DNA-damage | G35: Cell survival, apoptosis & mitophagy/DNA-damage | H35: General | I35: Other / not reported | J35: Not reported | K35: Other / unspecified | L35: Not reported | M35: Not reported | N35: Dlugosz PJ, Billen LP, Annis MG, Zhu W, Zhang Z, Lin J, Leber B, Andrews DW. Bcl-2 changes conformation to inhibit Bax oligomerization. EMBO J. 2006 Jun 7;25(11):2287-96. doi: 10.1038/sj.emboj.7601126. Epub 2006 Apr 27. PMID: 16642033; PMCID: PMC1478188. | O35: 10.1038/sj.emboj.7601126 | P35: 16642033 | R35: No notice found
A36: NPMT-I035 | B36: AKT1-E | C36: activation | D36: Bcl2 | E36: =IF(C36="inhibition",-1,1) -> 1 | F36: Metabolic & related | G36: Cell survival, apoptosis & mitophagy/DNA-damage | H36: Cartilage tissue | I36: Chondrocyte / cartilage | J36: Mouse | K36: Animal | L36: In vivo | M36: In vivo | N36: Qian J, Zhao P, Xu Q, Yang W, Cai R. Swimming prevents cell death of chondrocytes via PI3K/AKT pathway in an experimental model. J Orthop Surg Res. 2023 Jun 17;18(1):439. doi: 10.1186/s13018-023-03815-4. PMID: 37328786; PMCID: PMC10276397. | O36: 10.1186/s13018-023-03815-4 | P36: 37328786 | R36: No notice found
A37: NPMT-I036 | B37: AKT1-M | C37: activation | D37: Bcl2 | E37: =IF(C37="inhibition",-1,1) -> 1 | F37: Metabolic & related | G37: Cell survival, apoptosis & mitophagy/DNA-damage | H37: Cartilage tissue | I37: Chondrocyte / cartilage | J37: Mouse | K37: Animal | L37: In vivo | M37: In vivo | N37: Qian J, Zhao P, Xu Q, Yang W, Cai R. Swimming prevents cell death of chondrocytes via PI3K/AKT pathway in an experimental model. J Orthop Surg Res. 2023 Jun 17;18(1):439. doi: 10.1186/s13018-023-03815-4. PMID: 37328786; PMCID: PMC10276397. | O37: 10.1186/s13018-023-03815-4 | P37: 37328786 | R37: No notice found
A38: NPMT-I037 | B38: CREB | C38: activation | D38: Bcl2 | E38: =IF(C38="inhibition",-1,1) -> 1 | F38: Transcription Factors | G38: Cell survival, apoptosis & mitophagy/DNA-damage | H38: chondrocytes | I38: Chondrocyte / cartilage | J38: Mouse | K38: Animal | L38: in vivo | M38: In vivo | N38: Ma Q, Li X, Vale-Cruz D, Brown ML, Beier F, LuValle P. Activating transcription factor 2 controls Bcl-2 promoter activity in growth plate chondrocytes. J Cell Biochem. 2007 May 15;101(2):477-87. doi: 10.1002/jcb.21198. PMID: 17219413. | O38: 10.1002/jcb.21198 | P38: 17219413 | R38: No notice found
A39: NPMT-I038 | B39: PPARγ | C39: activation | D39: Bcl2 | E39: =IF(C39="inhibition",-1,1) -> 1 | F39: Transcription Factors | G39: Cell survival, apoptosis & mitophagy/DNA-damage | H39: NP | I39: NP / nucleus pulposus | J39: Human/Rat | K39: Human | L39: 2D, in vitro | M39: In vitro | N39: Cheng P, Wei HZ, Chen HW, Wang ZQ, Mao P, Zhang HH. DNMT3a-mediated methylation of PPARγ promote intervertebral disc degeneration by regulating the NF-κB pathway. J Cell Mol Med. 2024 Jan;28(2):e18048. doi: 10.1111/jcmm.18048. Epub 2023 Nov 20. PMID: 37986543; PMCID: PMC10826446. | O39: 10.1111/jcmm.18048 | P39: 37986543 | R39: No notice found
A40: NPMT-I039 | B40: BAD | C40: inhibition | D40: Bcl2 | E40: =IF(C40="inhibition",-1,1) -> -1 | F40: Other / unclassified | G40: Cell survival, apoptosis & mitophagy/DNA-damage | H40: General | I40: Other / not reported | J40: Not reported | K40: Other / unspecified | L40: Not reported | M40: Not reported | N40: Kale, J., Osterlund, E. & Andrews, D. BCL-2 family proteins: changing partners in the dance towards death. Cell Death Differ 25, 65–80 (2018). https://doi.org/10.1038/cdd.2017.186 | O40: 10.1038/cdd.2017.186 | R40: No notice found
...

Sheet Summary statistics
A1: Summary statistics of the interaction corpus
A2: All counts are formulas on the 'Interactions' sheet and refer to interactions (rows), not to distinct publications.
A4: Key figures
A5: Interactions | B5: =COUNTA(Interactions!$A$2:$A$354) -> 353
A6: Activating | B6: =COUNTIF(Interactions!$C$2:$C$354,"activation") -> 277
A7: Inhibitory | B7: =COUNTIF(Interactions!$C$2:$C$354,"inhibition") -> 76
A8: Interactions with at least one DOI | B8: =COUNTIF(Interactions!$O$2:$O$354,"?*") -> 322
A9: Interactions with an evidence note (reviewed) | B9: =COUNTIF(Interactions!$Q$2:$Q$354,"?*") -> 37
A10: Interactions whose references carry a retraction or concern notice | B10: =COUNTIF(Interactions!$R$2:$R$354,"NOTICE*") -> 0
A11: Interactions whose reference is also cited in Table S2 | B11: =COUNTIF(Interactions!$S$2:$S$354,"?*") -> 5
A12: Distinct DOIs cited | B12: 235
A14: Cell type of the supporting evidence
A15: Cell-type group | B15: Interactions | C15: Share
A16: NP / nucleus pulposus | B16: =COUNTIF(Interactions!$I$2:$I$354,A16) -> 108 | C16: =B16/$B$19 -> 0.30594901
A17: Chondrocyte / cartilage | B17: =COUNTIF(Interactions!$I$2:$I$354,A17) -> 75 | C17: =B17/$B$19 -> 0.21246459
A18: Other / not reported | B18: =COUNTIF(Interactions!$I$2:$I$354,A18) -> 170 | C18: =B18/$B$19 -> 0.4815864
A19: Total | B19: =SUM(B16:B18) -> 353 | C19: =B19/B19 -> 1
A22: Species of the experimental model
A23: Species group | B23: Interactions | C23: Share
A24: Human | B24: =COUNTIF(Interactions!$K$2:$K$354,A24) -> 114 | C24: =B24/$B$27 -> 0.32294618
A25: Animal | B25: =COUNTIF(Interactions!$K$2:$K$354,A25) -> 75 | C25: =B25/$B$27 -> 0.21246459
A26: Other / unspecified | B26: =COUNTIF(Interactions!$K$2:$K$354,A26) -> 164 | C26: =B26/$B$27 -> 0.46458924
A27: Total | B27: =SUM(B24:B26) -> 353 | C27: =B27/B27 -> 1
A30: Experimental setting
A31: Culture group | B31: Interactions | C31: Share
A32: In vitro | B32: =COUNTIF(Interactions!$M$2:$M$354,A32) -> 166 | C32: =B32/$B$37 -> 0.47025496
A33: Ex vivo | B33: =COUNTIF(Interactions!$M$2:$M$354,A33) -> 16 | C33: =B33/$B$37 -> 0.045325779
A34: In vivo | B34: =COUNTIF(Interactions!$M$2:$M$354,A34) -> 7 | C34: =B34/$B$37 -> 0.019830028
A35: Mixed | B35: =COUNTIF(Interactions!$M$2:$M$354,A35) -> 10 | C35: =B35/$B$37 -> 0.028328612
A36: Not reported | B36: =COUNTIF(Interactions!$M$2:$M$354,A36) -> 154 | C36: =B36/$B$37 -> 0.43626062
A37: Total | B37: =SUM(B32:B36) -> 353 | C37: =B37/B37 -> 1
A40: Interactions by functional module
A41: Functional module | B41: Outgoing (source) | C41: Incoming (target) | D41: Within module
A42: Cytokines, chemokines, proteases & others | B42: =COUNTIF(Interactions!$F$2:$F$354,A42) -> 0 | C42: =COUNTIF(Interactions!$G$2:$G$354,A42) -> 40 | D42: =COUNTIFS(Interactions!$F$2:$F$354,A42,Interactions!$G$2:$G$354,A42) -> 0
A43: Growth factors | B43: =COUNTIF(Interactions!$F$2:$F$354,A43) -> 0 | C43: =COUNTIF(Interactions!$G$2:$G$354,A43) -> 32 | D43: =COUNTIFS(Interactions!$F$2:$F$354,A43,Interactions!$G$2:$G$354,A43) -> 0
A44: Transcription Factors | B44: =COUNTIF(Interactions!$F$2:$F$354,A44) -> 131 | C44: =COUNTIF(Interactions!$G$2:$G$354,A44) -> 64 | D44: =COUNTIFS(Interactions!$F$2:$F$354,A44,Interactions!$G$2:$G$354,A44) -> 12
A45: Ion channels & related | B45: =COUNTIF(Interactions!$F$2:$F$354,A45) -> 20 | C45: =COUNTIF(Interactions!$G$2:$G$354,A45) -> 25 | D45: =COUNTIFS(Interactions!$F$2:$F$354,A45,Interactions!$G$2:$G$354,A45) -> 9
A46: Metabolic & related | B46: =COUNTIF(Interactions!$F$2:$F$354,A46) -> 57 | C46: =COUNTIF(Interactions!$G$2:$G$354,A46) -> 64 | D46: =COUNTIFS(Interactions!$F$2:$F$354,A46,Interactions!$G$2:$G$354,A46) -> 31
A47: ECM anabolism & phenotype markers | B47: =COUNTIF(Interactions!$F$2:$F$354,A47) -> 0 | C47: =COUNTIF(Interactions!$G$2:$G$354,A47) -> 19 | D47: =COUNTIFS(Interactions!$F$2:$F$354,A47,Interactions!$G$2:$G$354,A47) -> 0
A48: Mechanical stimuli & its receptors | B48: =COUNTIF(Interactions!$F$2:$F$354,A48) -> 27 | C48: =COUNTIF(Interactions!$G$2:$G$354,A48) -> 15 | D48: =COUNTIFS(Interactions!$F$2:$F$354,A48,Interactions!$G$2:$G$354,A48) -> 15
...

Sheet Evidence review
A1: Evidence review of 37 interactions
A2: Interactions whose supporting evidence was added or re-examined during curation, with the classification of that evidence. Interactions supported only by indirect, contextual, partial or conflicting evidence are kept in the network and flagged here for transparency.
A4: Interaction ID | B4: Source | C4: Target | D4: Sign | E4: Evidence class | F4: Cell type / model | G4: Publication | H4: What was shown | I4: Interpretation / limitation | J4: Used as support in corpus | K4: Retraction screen
A5: NPMT-I001 | B5: HIF-1α | C5: ACAN | D5: =IF(INDEX(Interactions!$C:$C,MATCH(A5,Interactions!$A:$A,0))="inhibition",-1,1) -> 1 | E5: Supported in NP | F5: See original evidence review / CORPUS metadata | G5: Liu Z, Li C, Meng X, Bai Y, Qi J, Wang J, Zhou Q, Zhang W, Zhang X. Hypoxia-inducible factor-1α mediates aggrecan and collagen II expression via NOTCH1 signaling in nucleus pulposus cells during intervertebral disc degeneration. Biochem Biophys Res Commun. 2017;488(3):554-561. doi: 10.1016/j.bbrc.2017.05.086. PMID: 28526405. | H5: HIF-1α overexpression increased aggrecan | I5: Retained literature where relevant; compartment and direction must match. HIF-1α overexpression increased aggrecan | J5: Yes | K5: No notice found
A6: NPMT-I007 | B6: P38 | C6: ADAMTS4/5 | D6: =IF(INDEX(Interactions!$C:$C,MATCH(A6,Interactions!$A:$A,0))="inhibition",-1,1) -> 1 | E6: Partial: ADAMTS4 only | F6: See original evidence review / CORPUS metadata | G6: Xue J, Wang J, Liu Q, Luo A. Tumor necrosis factor-α induces ADAMTS-4 expression in human osteoarthritis chondrocytes. Mol Med Rep. 2013;8(6):1755-1760. doi: 10.3892/mmr.2013.1729. PMID: 24126638. | H6: p38 dependent TNF-α induction of ADAMTS4; NOT demonstrated for ADAMTS5 | I6: Retained literature where relevant; compartment and direction must match. p38 dependent TNF-α induction of ADAMTS4; NOT demonstrated for ADAMTS5 | J6: Yes | K6: No notice found
A7: NPMT-I011 | B7: PIP3-M | C7: AKT1-E | D7: =IF(INDEX(Interactions!$C:$C,MATCH(A7,Interactions!$A:$A,0))="inhibition",-1,1) -> -1 | E7: Contextual; direction conflicts | F7: Other mammalian cells / biochemical | G7: Stokoe D, Stephens LR, Copeland T, Gaffney PR, Reese CB, Painter GF, Holmes AB, McCormick F, Hawkins PT. Dual role of phosphatidylinositol-3,4,5-trisphosphate in the activation of protein kinase B. Science. 1997;277(5325):567-570. doi: 10.1126/science.277.5325.567. PMID: 9228007. | H7: PIP3 recruits and promotes activation of AKT; no M-to-E cross-compartment inhibition shown | I7: Cited because it directly studies PIP3 and AKT1, but it supports activation and does not validate negative sign or M/E topology | J7: Yes — contextual only | K7: No notice found
A8: NPMT-I014 | B8: PIP3-E | C8: AKT1-M | D8: =IF(INDEX(Interactions!$C:$C,MATCH(A8,Interactions!$A:$A,0))="inhibition",-1,1) -> -1 | E8: Contextual; direction conflicts | F8: Other mammalian cells / biochemical | G8: Stokoe D, Stephens LR, Copeland T, Gaffney PR, Reese CB, Painter GF, Holmes AB, McCormick F, Hawkins PT. Dual role of phosphatidylinositol-3,4,5-trisphosphate in the activation of protein kinase B. Science. 1997;277(5325):567-570. doi: 10.1126/science.277.5325.567. PMID: 9228007. | H8: PIP3 recruits and promotes activation of AKT; no E-to-M cross-compartment inhibition shown | I8: Same primary paper supports generic PIP3–AKT molecular interaction, not negative sign or compartment-specific effect | J8: Yes — contextual only | K8: No notice found
A9: NPMT-I015 | B9: Ca2+os | C9: AMPK | D9: =IF(INDEX(Interactions!$C:$C,MATCH(A9,Interactions!$A:$A,0))="inhibition",-1,1) -> 1 | E9: Indirect mechanistic support | F9: Mammalian cells | G9: Woods A, Dickerson K, Heath R, et al. Ca2+/calmodulin-dependent protein kinase kinase-beta acts upstream of AMP-activated protein kinase in mammalian cells. Cell Metab. 2005;2(1):21-33. doi: 10.1016/j.cmet.2005.06.005. PMID: 16054096. | H9: Ca2+ can activate AMPK via CaMKKβ; osmotic compartment not tested. | I9: Selected due to experimentally measured relationship; sign/context caveat recorded | J9: Yes — contextual or indirect | K9: No notice found
A10: NPMT-I017 | B10: ROS | C10: AMPK | D10: =IF(INDEX(Interactions!$C:$C,MATCH(A10,Interactions!$A:$A,0))="inhibition",-1,1) -> 1 | E10: Supported in other cells | F10: See original evidence review / CORPUS metadata | G10: Emerling BM, Weinberg F, Snyder C, Burgess Z, Mutlu GM, Viollet B, Budinger GRS, Chandel NS. Hypoxic activation of AMPK is dependent on mitochondrial ROS but independent of an increase in AMP/ATP ratio. Free Radic Biol Med. 2009;46(10):1386-1391. doi: 10.1016/j.freeradbiomed.2009.02.019. PMID: 19268526. | H10: ROS-dependent AMPK activation in hypoxic cultured cells; not NP-specific | I10: Retained literature where relevant; compartment and direction must match. ROS-dependent AMPK activation in hypoxic cultured cells; not NP-specific | J10: Yes | K10: No notice found
A11: NPMT-I024 | B11: SOX9 | C11: AP-1 | D11: =IF(INDEX(Interactions!$C:$C,MATCH(A11,Interactions!$A:$A,0))="inhibition",-1,1) -> -1 | E11: Contextual / contradictory; retained at curators' discretion | F11: Mouse chondrocytes; epidermal stem cells | G11: He X, Ohba S, Hojo H, McMahon AP. AP-1 family members act with Sox9 to promote chondrocyte hypertrophy. Development. 2016;143(16):3012-3023. doi: 10.1242/dev.134502. PMID: 27471255. Yang Y, Gomez N, Infarinato N, et al. The pioneer factor SOX9 competes for epigenetic factors to switch stem cell fates. Nat Cell Biol. 2023;25:1185-1195. doi: 10.1038/s41556-023-01184-y. | H11: Context-dependent cooperation or altered occupancy; not general inhibition. | I11: Included per request; NOT direct evidence of negative signed compartment-specific edge. | J11: Yes — caveated | K11: No notice found
A12: NPMT-I047 | B12: IP3 | C12: Ca2+su | D12: =IF(INDEX(Interactions!$C:$C,MATCH(A12,Interactions!$A:$A,0))="inhibition",-1,1) -> 1 | E12: Supported in chondrocytes | F12: See original evidence review / CORPUS metadata | G12: Ekstein J, Nasatzky E, Boyan BD, Ornoy A, Schwartz Z. Growth-plate chondrocytes respond to 17beta-estradiol with sex-specific increases in IP3 and intracellular calcium ion signalling via a capacitative entry mechanism. Steroids. 2005;70(11):775-786. doi: 10.1016/j.steroids.2005.04.007. PMID: 16005036. | H12: IP3 production drives calcium release from endoplasmic reticulum | I12: Retained literature where relevant; compartment and direction must match. IP3 production drives calcium release from endoplasmic reticulum | J12: Yes | K12: No notice found
A13: NPMT-I055 | B13: FOXO | C13: CAT | D13: =IF(INDEX(Interactions!$C:$C,MATCH(A13,Interactions!$A:$A,0))="inhibition",-1,1) -> 1 | E13: Supported in chondrocytes | F13: See original evidence review / CORPUS metadata | G13: Akasaki Y, Alvarez-Garcia O, Saito M, Caramés B, Iwamoto Y, Lotz MK. FoxO transcription factors support oxidative stress resistance in human chondrocytes. Arthritis Rheumatol. 2014;66(12):3349-3358. doi: 10.1002/art.38868. PMID: 25186470. | H13: FOXO1 knockdown reduced catalase protein under oxidative challenge | I13: Retained literature where relevant; compartment and direction must match. FOXO1 knockdown reduced catalase protein under oxidative challenge | J13: Yes | K13: No notice found
A14: NPMT-I072 | B14: HIF-1α | C14: COL2A1 | D14: =IF(INDEX(Interactions!$C:$C,MATCH(A14,Interactions!$A:$A,0))="inhibition",-1,1) -> 1 | E14: Supported in NP | F14: See original evidence review / CORPUS metadata | G14: Liu Z, Li C, Meng X, Bai Y, Qi J, Wang J, Zhou Q, Zhang W, Zhang X. Hypoxia-inducible factor-1α mediates aggrecan and collagen II expression via NOTCH1 signaling in nucleus pulposus cells during intervertebral disc degeneration. Biochem Biophys Res Commun. 2017;488(3):554-561. doi: 10.1016/j.bbrc.2017.05.086. PMID: 28526405. | H14: HIF-1α overexpression increased type II collagen | I14: Retained literature where relevant; compartment and direction must match. HIF-1α overexpression increased type II collagen | J14: Yes | K14: No notice found
A15: NPMT-I090 | B15: ROS | C15: DRP1 | D15: =IF(INDEX(Interactions!$C:$C,MATCH(A15,Interactions!$A:$A,0))="inhibition",-1,1) -> 1 | E15: indirect / pathway-level | F15: NP cells | G15: Su S, Wu X, Li B, et al. Inhibition of ERK1/2 mediated activation of Drp1 alleviates intervertebral disc degeneration via suppressing pyroptosis and apoptosis in nucleus pulposus cells. J Orthop Translat. 2025;51:163-175. doi: 10.1016/j.jot.2025.01.013. PMID: 40160807. | H15: Indirect NP evidence: oxidative stress (TBHP) was associated with ERK1/2-dependent Drp1 activation; ROS itself was not established as the direct activator. | I15: Chosen as published experimental evidence; limitations: Indirect NP evidence: oxidative stress (TBHP) was associated with ERK1/2-dependent Drp1 activation; ROS itself was not established as the direct activator. | J15: No | K15: No notice found
A16: NPMT-I092 | B16: MAP3K | C16: ELK1 | D16: =IF(INDEX(Interactions!$C:$C,MATCH(A16,Interactions!$A:$A,0))="inhibition",-1,1) -> 1 | E16: indirect / pathway-level | F16: Other mammalian cells | G16: Cruzalegui FH, Cano E, Treisman R. ERK activation induces phosphorylation of Elk-1 at multiple S/T-P motifs to high stoichiometry. Oncogene. 1999;18:7948-7957. doi: 10.1038/sj.onc.1203362. PMID: 10637505. | H16: Pathway-level only: MAP3K activates downstream MAPK signalling which phosphorylates ELK1. Direct MAP3K-to-ELK1 action not shown. | I16: Chosen as published experimental evidence; limitations: Pathway-level only: MAP3K activates downstream MAPK signalling which phosphorylates ELK1. Direct MAP3K-to-ELK1 action not shown. | J16: No | K16: No notice found
... A41: NPMT-I353 | B41: ROS | C41: MitD | D41: =IF(INDEX(Interactions!$C:$C,MATCH(A41,Interactions!$A:$A,0))="inhibition",-1,1) -> 1 | E41: Supported in NP | F41: See original evidence review / CORPUS metadata | G41: Yang L, Zhu L, Dong W, Cao Y, Lin L, Rong Z, Zhang Z, Wu G. Reactive oxygen species-mediated mitochondrial dysfunction plays a critical role in high glucose-induced nucleus pulposus cell injury. Int Orthop. 2014;38(1):205-206. doi: 10.1007/s00264-013-2144-6. PMID: 24122049. | H41: ROS-mediated mitochondrial dysfunction in NP cells; interpret MitD as mitochondrial dysfunction | I41: Retained literature where relevant; compartment and direction must match. ROS-mediated mitochondrial dysfunction in NP cells; interpret MitD as mitochondrial dysfunction | J41: Yes | K41: No notice found

Sheet Retraction screen
A1: Retraction screen of cited publications
A2: Each DOI cited in the corpus was queried in Crossref on 2026-10-11 for editorial updates linked to the record (retraction, withdrawal, removal, expression of concern), which include the Retraction Watch database. References without a DOI could not be screened this way.
A4: DOI | B4: Title (Crossref) | C4: Year | D4: Found in Crossref | E4: Editorial notices
A5: 10.1002/1529-0131(200103)44:3<595::aid-anr108>3.0.co;2-8 | B5: Peroxisome proliferator-activated receptor ? activators inhibit interleukin-1?-induced nitric oxide and matrix metalloproteinase 13 production in human chondrocytes | C5: 2001 | D5: Yes | E5: None
A6: 10.1002/1529-0131(200110)44:10<2296::aid-art392>3.0.co;2-9 | B6: Synergistic induction of matrix metalloproteinase 1 by interleukin-1? and oncostatin M in human chondrocytes involves signal transducer and activator of transcription and activator protein 1 transcription factors via a novel mechanism | C6: 2001 | D6: Yes | E6: None
A7: 10.1002/advs.202105466 | B7: Prussian Blue Nanoparticles Stabilize SOD1 from Ubiquitination‐Proteasome Degradation to Rescue Intervertebral Disc Degeneration | C7: 2022 | D7: Yes | E7: None
A8: 10.1002/art.23504 | B8: Differential expression of GADD45β in normal and osteoarthritic cartilage: Potential role in homeostasis of articular chondrocytes | C8: 2008 | D8: Yes | E8: None
A9: 10.1002/art.24073 | B9: Cited2 modulates hypoxia‐inducible factor–dependent expression of vascular endothelial growth factor in nucleus pulposus cells of the rat intervertebral disc | C9: 2008 | D9: Yes | E9: None
A10: 10.1002/art.25051 | B10: Rho kinase–dependent activation of SOX9 in chondrocytes | C10: 2009 | D10: Yes | E10: None
A11: 10.1002/art.38791 | B11: Peroxisome Proliferator–Activated Receptor γ Coactivator 1α and FoxO3A Mediate Chondroprotection by AMP‐Activated Protein Kinase | C11: 2014 | D11: Yes | E11: None
A12: 10.1002/art.38868 | B12: FoxO Transcription Factors Support Oxidative Stress Resistance in Human Chondrocytes | C12: 2014 | D12: Yes | E12: None
A13: 10.1002/cbin.11293 | B13: Protective effects of cilengitide on inflammation in chondrocytes under excessive mechanical stress | C13: 2020 | D13: Yes | E13: None
A14: 10.1002/dvdy.20323 | B14: Runx2 regulates FGF2‐induced <i>Bmp2</i> expression during cranial bone development | C14: 2005 | D14: Yes | E14: None
A15: 10.1002/humu.9503 | B15: Genetic variant in theHSPB1 promoter region impairs the HSP27 stress response | C15: 2007 | D15: Yes | E15: None
A16: 10.1002/jbmr.174 | B16: SOX9 determines RUNX2 transactivity by directing intracellular degradation | C16: 2010 | D16: Yes | E16: None
... A239: 10.4049/jimmunol.1402554 | B239: Cutting Edge: Differential Regulation of PTEN by TCR, Akt, and FoxO1 Controls CD4+ T Cell Fate Decisions | C239: 2015 | D239: Yes | E239: None
